Exception ignored in: <bound method PhotoImage.__del__ of <PIL.ImageTk.PhotoImage object at 0x7eff535394a8>>
Traceback (most recent call last):
  File "/home/paol/.local/lib/python3.6/site-packages/PIL/ImageTk.py", line 130, in __del__
    name = self.__photo.name
AttributeError: 'PhotoImage' object has no attribute '_PhotoImage__photo'
Exception ignored in: <bound method PhotoImage.__del__ of <PIL.ImageTk.PhotoImage object at 0x7eff28b9a128>>
Traceback (most recent call last):
  File "/home/paol/.local/lib/python3.6/site-packages/PIL/ImageTk.py", line 130, in __del__
    name = self.__photo.name
AttributeError: 'PhotoImage' object has no attribute '_PhotoImage__photo'
Exception ignored in: <bound method PhotoImage.__del__ of <PIL.ImageTk.PhotoImage object at 0x7eff28b9a0f0>>
Traceback (most recent call last):
  File "/home/paol/.local/lib/python3.6/site-packages/PIL/ImageTk.py", line 130, in __del__
    name = self.__photo.name
AttributeError: 'PhotoImage' object has no attribute '_PhotoImage__photo'
Exception ignored in: <bound method PhotoImage.__del__ of <PIL.ImageTk.PhotoImage object at 0x7eff28ba0c18>>
Traceback (most recent call last):
  File "/home/paol/.local/lib/python3.6/site-packages/PIL/ImageTk.py", line 130, in __del__
    name = self.__photo.name
AttributeError: 'PhotoImage' object has no attribute '_PhotoImage__photo'
